Workbook

Sheet pipeline_collection
B1: Commodity
A2: Conversion rate | C2: €/$ | D2: 0.88
A3: Energy denstiy | B3: H2 | C3: MWh/t | D3: 33.33 | E3: MWh/m³ | F3: 1.4 | G3: 700 bar | H3: https://www.wasserstoff-leitprojekte.de/lw_resource/datapool/systemfiles/elements/files/F4941D1CBA383928E0537E695E862E63/live/document/Wasserstoff-Verfl%C3%BCssigung,_Speicherung,_Transport_und_Anwendung_von_fl%C3%BCssigem_Wasserstoff__2_.pdf | S3: Volumenstromrechnung Wasserstoffpipeline | T3: Q_H2 [Nm³/h] = 3.7435·10⁻³ · (Tn/pn) · [(p1² - p2²)/(G_H2 · L · T · Z)]^0.5 · D^2.667
A4: Energy denstiy | B4: H2 | C4: MWh/t | D4: 33.33 | E4: MWh/m³ | F4: 2.3 | G4: ="-253°C" -> -253°C
A5: Energy denstiy | B5: NH3 | C5: MWh/t | D5: 5.2 | E5: MWh/m³ | F5: 3.6 | H5: https://www.wasserstoff-leitprojekte.de/lw_resource/datapool/systemfiles/elements/files/F4941D1CBA383928E0537E695E862E63/live/document/Wasserstoff-Verfl%C3%BCssigung,_Speicherung,_Transport_und_Anwendung_von_fl%C3%BCssigem_Wasserstoff__2_.pdf | S5: Literature Value
A6: Energy denstiy | B6: MeOH | C6: MWh/t | D6: 5.5 | E6: MWh/m³ | F6: 4.4 | S6: Calculated Value
A7: Energy denstiy | B7: SNG | C7: MWh/t | D7: 13.9 | E7: MWh/m³ | F7: 6.6 | S7: Expert assumption
A8: Energy denstiy | B8: Diesel | C8: MWh/t | D8: 11.9 | E8: MWh/m³ | F8: 9.8 | H8: https://www.wasserstoff-leitprojekte.de/lw_resource/datapool/systemfiles/elements/files/F4941D1CBA383928E0537E695E862E63/live/document/Wasserstoff-Verfl%C3%BCssigung,_Speicherung,_Transport_und_Anwendung_von_fl%C3%BCssigem_Wasserstoff__2_.pdf | S8: AI value
A10: Invest Cost | B10: €/MW/km | C10: 267 | F10: Welder et al https://doi.org/10.1016/j.energy.2018.05.059, PyPSA | S10: G_h2 | T10: - | U10: 0.0696
A11: Invest cost for rated capacity 6 GW | B11: €/km | C11: 1600000 | F11: Welder et al https://doi.org/10.1016/j.energy.2018.05.059
A12: fom | B12: €/km/a | C12: =5*1000 -> 5000 | F12: Welder et al https://doi.org/10.1016/j.energy.2018.05.059
A13: Investment cost fee for transported energy | B13: €/MWh/km | C13: =(C11*C25+C12)/(18000*C22) -> 0.001183454 | F13: Welder et al https://doi.org/10.1016/j.energy.2018.05.059
A14: Invest cost for rated capacity | B14: €/km | C14: =C10*E23 -> 3471000 | S14: Tn
A15: Diameter | B15: m | C15: =T41/1000 -> 0.99
A16: Pipeline invest cost per diameter | B16: $/m | C16: =3200*C15^2+478.9*C15+263.2 -> 3873.631 | D16: €/km | E16: =C16*D2*1000 -> 3408795.3 | F16: IEA, 2019, Belfer-Center Report
A17: Lifetime | B17: a | C17: 50 | F17: Leenings, 2024; Flamme, 2021 | S17: pn
A18: Lifetime | B18: a | C18: 40 | F18: Welder et al https://doi.org/10.1016/j.energy.2018.05.059
A19: WACC | B19: - | C19: 0.06 | S19: deltap
A20: Cost share piping | B20: - | C20: 0.6 | F20: https://ehb.eu/files/downloads/2020_European-Hydrogen-Backbone_Report.pdf | S20: L
A21: Cast share compressors | B21: - | C21: 0.4 | F21: https://ehb.eu/files/downloads/2020_European-Hydrogen-Backbone_Report.pdf | S21: T
A22: Load factor | B22: h/a | C22: 5000 | D22: - | E22: =C22/8760 -> 0.57077626 | F22: https://ehb.eu/files/downloads/2020_European-Hydrogen-Backbone_Report.pdf | S22: Z
A23: Capacity of hydrogen flow (at full load factor) | B23: GW | C23: 13 | D23: MW | E23: =C23*1000 -> 13000 | F23: https://ehb.eu/files/downloads/2020_European-Hydrogen-Backbone_Report.pdf | S23: D
A24: Pipeline diameter | B24: " | C24: 48 | D24: cm | E24: =C24*2.54 -> 121.92 | F24: https://ehb.eu/files/downloads/2020_European-Hydrogen-Backbone_Report.pdf
A25: Annuity factor | B25: a | C25: =((1+C19)^C17*C19)/((1+C19)^C17-1) -> 0.063444286 | T25: Inner diameter | U25: Specific capital costs | V25: °Q_h2 | W25: P_transport | X25: Look up table capacity
A26: Annuity | B26: €/km/a | C26: =C25*C14 -> 220215.12 | T26: mm | U26: €/km | V26: Nm³/h | W26: MW | X26: GW min | Y26: GW mean | Z26: GW max
A27: Transported energy amount | B27: MWh | C27: =E23*C22 -> 65000000 | S27: DN100 | W27: =V27*10.8/3600 -> 0
A28: Investment cost fee for transported energy | B28: €/MWh/km/a | C28: =C26/C27 -> 0.0033879249 | S28: DN125 | W28: =V28*10.8/3600 -> 0
C29: Low | D29: Medium | E29: High | F29: Source | S29: DN150 | W29: =V29*10.8/3600 -> 0
A30: OPEX excluding electricity | B30: €/km/a | C30: =0.7*10^9/22900 -> 30567.686 | D30: =0.9*10^9/22900 -> 39301.31 | E30: =1.1*10^9/22900 -> 48034.934 | F30: https://ehb.eu/files/downloads/2020_European-Hydrogen-Backbone_Report.pdf | Q30: Verteilende Fernleitungen | S30: DN200 | W30: =V30*10.8/3600 -> 0
A31: Electricity demand as share of transported hydrogen energy at 57% load share for every 1000km electric compression | B31: 1/1000km | C31: 0.015 | D31: =(E31-C31)/2+C31 -> 0.019 | E31: 0.023 | F31: https://ehb.eu/files/downloads/2020_European-Hydrogen-Backbone_Report.pdf | S31: DN250 | W31: =V31*10.8/3600 -> 0
A32: Electricity demand as share of transported hydrogen energy at 57% load share for every km electric compression | B32: 1/km | C32: =C31/1000 -> 1.5e-05 | D32: =D31/1000 -> 1.9e-05 | E32: =E31/1000 -> 2.3e-05 | F32: https://ehb.eu/files/downloads/2020_European-Hydrogen-Backbone_Report.pdf | R32: Wasserstoff Fernleitungen | S32: DN300 | T32: 300 | W32: =V32*10.8/3600 -> 0 | X32: 1 | Z32: 1.3
A33: Distance between compressors | B33: km | C33: 100-600 | F33: https://ehb.eu/files/downloads/2020_European-Hydrogen-Backbone_Report.pdf | S33: DN350 | W33: =V33*10.8/3600 -> 0
A34: OPEX electricity costs | B34: €/km/a | C34: =0.9*10^9/22900 -> 39301.31 | D34: =1.2*10^9/22900 -> 52401.747 | E34: =2.4*10^9/22900 -> 104803.49 | F34: https://ehb.eu/files/downloads/2020_European-Hydrogen-Backbone_Report.pdf | P34: Hauptleitungen | S34: DN400 | T34: 400 | W34: =V34*10.8/3600 -> 0 | X34: 2 | Z34: 2.5
A35: TOTAL OPEX | B35: €/km/a | C35: =C34+C30 -> 69868.996 | D35: =D34+D30 -> 91703.057 | E35: =E34+E30 -> 152838.43 | F35: https://ehb.eu/files/downloads/2020_European-Hydrogen-Backbone_Report.pdf | S35: DN450 | W35: =V35*10.8/3600 -> 0
A36: Fom | B36: CAPEX/a | C36: =0.03 -> 0.03 | F36: PyPSA | S36: DN500 | T36: 500 | W36: =V36*10.8/3600 -> 0 | X36: 3.5 | Z36: 4
S37: DN600 | T37: 590 | W37: =V37*10.8/3600 -> 0 | X37: 5.5 | Z37: 6.5
A38: Exemplary assumptions | S38: DN700 | T38: 690 | W38: =V38*10.8/3600 -> 0 | X38: 8 | Z38: 9
A39: H2 | B39: pipeline | C39: 2021 | E39: €/MWhLHV | F39: 36 | G39: €/MWh | H39: =F39 -> 36 | I39: Hampp et al. | K39: Global import to germany | S39: DN800 | T39: 790 | W39: =V39*10.8/3600 -> 0 | X39: 11 | Z39: 13
A40: H2 | B40: pipeline | C40: 2021 | E40: €/MWhLHV | F40: 42 | G40: €/MWh | H40: =F40 -> 42 | I40: Hampp et al. | K40: Global import to germany | S40: DN900 | W40: =V40*10.8/3600 -> 0
A41: H2 | B41: pipeline | C41: 2022 | E41: $/kgH2 | F41: 0.66 | G41: €/MWh | H41: =F41*33.33 -> 21.9978 | I41: Di Lullo et al. | K41: at 1000km | S41: DN1000 | T41: 990 | W41: =V41*10.8/3600 -> 0 | X41: 18 | Z41: 22
...

Sheet pipeline_data
A1: name | B1: lon | C1: lat | D1: alternative | E1: commodity | F1: invest_cost_MWh | G1: lifetime | H1: WACC | I1: annuity_factor | J1: invest_cost | K1: DN | L1: capacity | M1: full_load_hours | N1: fom_cost_MWh | O1: regional_factor | P1: fom_capex_factor | Q1: vom_cost_MWh | R1: electricity_per_energy_transported | S1: cost_el | T1: total_cost_MWh
A2: AF-AGO | B2: 17.873887 | C2: -11.202692 | D2: Base | E2: h2 | F2: =(J2*I2)/(L2*M2) -> 0.0021213368 | G2: 40 | H2: 0.11794509 | I2: =((1+H2)^G2*H2)/((1+H2)^G2-1) -> 0.1193252 | J2: 1600000 | K2: 1000 | L2: 18000 | M2: 5000 | N2: =P2*F2*0.5*(1+O2) -> 3.5002058e-05 | O2: 0.1 | P2: 0.03 | Q2: =R2*S2 -> 0.0014444028 | R2: =0.019/1000 -> 1.9e-05 | S2: 76.0212 | T2: =F2+Q2+N2 -> 0.0036007417
A3: AF-BDI | B3: 29.918886 | C3: -3.373056 | D3: Base | E3: h2 | F3: =(J3*I3)/(L3*M3) -> 0.0040118804 | G3: 40 | H3: 0.22560228 | I3: =((1+H3)^G3*H3)/((1+H3)^G3-1) -> 0.22566827 | J3: 1600000 | K3: 1000 | L3: 18000 | M3: 5000 | N3: =P3*F3*0.5*(1+O3) -> 6.6196026e-05 | O3: 0.1 | P3: 0.03 | Q3: =R3*S3 -> 0.0015354261 | R3: =0.019/1000 -> 1.9e-05 | S3: 80.8119 | T3: =F3+Q3+N3 -> 0.0056135025
A4: AF-BEN | B4: 2.315834 | C4: 9.30769 | D4: Base | E4: h2 | F4: =(J4*I4)/(L4*M4) -> 0.0017838705 | G4: 40 | H4: 0.097954265 | I4: =((1+H4)^G4*H4)/((1+H4)^G4-1) -> 0.10034271 | J4: 1600000 | K4: 1000 | L4: 18000 | M4: 5000 | N4: =P4*F4*0.5*(1+O4) -> 2.9433863e-05 | O4: 0.1 | P4: 0.03 | Q4: =R4*S4 -> 0.0014811051 | R4: =0.019/1000 -> 1.9e-05 | S4: 77.9529 | T4: =F4+Q4+N4 -> 0.0032944094
A5: AF-BFA | B5: -1.561593 | C5: 12.238333 | D5: Base | E5: h2 | F5: =(J5*I5)/(L5*M5) -> 0.0022505015 | G5: 40 | H5: 0.1254712 | I5: =((1+H5)^G5*H5)/((1+H5)^G5-1) -> 0.12659071 | J5: 1600000 | K5: 1000 | L5: 18000 | M5: 5000 | N5: =P5*F5*0.5*(1+O5) -> 3.7133275e-05 | O5: 0.1 | P5: 0.03 | Q5: =R5*S5 -> 0.0014427916 | R5: =0.019/1000 -> 1.9e-05 | S5: 75.9364 | T5: =F5+Q5+N5 -> 0.0037304264
A6: AF-BWA | B6: 24.684866 | C6: -22.328474 | D6: Base | E6: h2 | F6: =(J6*I6)/(L6*M6) -> 0.0013457921 | G6: 40 | H6: 0.070793106 | I6: =((1+H6)^G6*H6)/((1+H6)^G6-1) -> 0.075700804 | J6: 1600000 | K6: 1000 | L6: 18000 | M6: 5000 | N6: =P6*F6*0.5*(1+O6) -> 2.2205569e-05 | O6: 0.1 | P6: 0.03 | Q6: =R6*S6 -> 0.0008967145 | R6: =0.019/1000 -> 1.9e-05 | S6: 47.1955 | T6: =F6+Q6+N6 -> 0.0022647121
A7: AF-CAF | B7: 20.939444 | C7: 6.611111 | D7: Base | E7: h2 | F7: =(J7*I7)/(L7*M7) -> 0.0040118804 | G7: 40 | H7: 0.22560228 | I7: =((1+H7)^G7*H7)/((1+H7)^G7-1) -> 0.22566827 | J7: 1600000 | K7: 1000 | L7: 18000 | M7: 5000 | N7: =P7*F7*0.5*(1+O7) -> 6.6196026e-05 | O7: 0.1 | P7: 0.03 | Q7: =R7*S7 -> 0.0014456454 | R7: =0.019/1000 -> 1.9e-05 | S7: 76.0866 | T7: =F7+Q7+N7 -> 0.0055237218
A8: AF-CIV | B8: -5.54708 | C8: 7.539989 | D8: Base | E8: h2 | F8: =(J8*I8)/(L8*M8) -> 0.0015937035 | G8: 40 | H8: 0.08638626 | I8: =((1+H8)^G8*H8)/((1+H8)^G8-1) -> 0.089645824 | J8: 1600000 | K8: 1000 | L8: 18000 | M8: 5000 | N8: =P8*F8*0.5*(1+O8) -> 2.6296108e-05 | O8: 0.1 | P8: 0.03 | Q8: =R8*S8 -> 0.0014175368 | R8: =0.019/1000 -> 1.9e-05 | S8: 74.6072 | T8: =F8+Q8+N8 -> 0.0030375365
A9: AF-CMR | B9: 12.354722 | C9: 7.369722 | D9: Base | E9: h2 | F9: =(J9*I9)/(L9*M9) -> 0.0022073246 | G9: 40 | H9: 0.12296142 | I9: =((1+H9)^G9*H9)/((1+H9)^G9-1) -> 0.12416201 | J9: 1600000 | K9: 1000 | L9: 18000 | M9: 5000 | N9: =P9*F9*0.5*(1+O9) -> 3.6420856e-05 | O9: 0.1 | P9: 0.03 | Q9: =R9*S9 -> 0.0015079787 | R9: =0.019/1000 -> 1.9e-05 | S9: 79.3673 | T9: =F9+Q9+N9 -> 0.0037517242
A10: AF-COD | B10: 21.758664 | C10: -4.038333 | D10: Base | E10: h2 | F10: =(J10*I10)/(L10*M10) -> 0.0020817976 | G10: 40 | H10: 0.11562961 | I10: =((1+H10)^G10*H10)/((1+H10)^G10-1) -> 0.11710111 | J10: 1600000 | K10: 1000 | L10: 18000 | M10: 5000 | N10: =P10*F10*0.5*(1+O10) -> 3.434966e-05 | O10: 0.1 | P10: 0.03 | Q10: =R10*S10 -> 0.0014910041 | R10: =0.019/1000 -> 1.9e-05 | S10: 78.4739 | T10: =F10+Q10+N10 -> 0.0036071513
A11: AF-COG | B11: 15.827659 | C11: -0.228021 | D11: Base | E11: h2 | F11: =(J11*I11)/(L11*M11) -> 0.00248294 | G11: 40 | H11: 0.13889675 | I11: =((1+H11)^G11*H11)/((1+H11)^G11-1) -> 0.13966537 | J11: 1600000 | K11: 1000 | L11: 18000 | M11: 5000 | N11: =P11*F11*0.5*(1+O11) -> 4.0968509e-05 | O11: 0.1 | P11: 0.03 | Q11: =R11*S11 -> 0.0014880914 | R11: =0.019/1000 -> 1.9e-05 | S11: 78.3206 | T11: =F11+Q11+N11 -> 0.0040119999
A12: AF-CPV | B12: -24.013197 | C12: 16.002082 | D12: Base | E12: h2 | F12: =(J12*I12)/(L12*M12) -> 0.0040118804 | G12: 40 | H12: =MAX($H$2:$H$11,$H$13:$H$16,$H$18:$H$33,$H$35:$H$52) -> 0.22560228 | I12: =((1+H12)^G12*H12)/((1+H12)^G12-1) -> 0.22566827 | J12: 1600000 | K12: 1000 | L12: 18000 | M12: 5000 | N12: =P12*F12*0.5*(1+O12) -> 6.6196026e-05 | O12: 0.1 | P12: 0.03 | Q12: =R12*S12 -> 0.0016339069 | R12: =0.019/1000 -> 1.9e-05 | S12: 85.9951 | T12: =F12+Q12+N12 -> 0.0057119833
A13: AF-DJI | B13: 42.590275 | C13: 11.825138 | D13: Base | E13: h2 | F13: =(J13*I13)/(L13*M13) -> 0.0040118804 | G13: 40 | H13: 0.22560228 | I13: =((1+H13)^G13*H13)/((1+H13)^G13-1) -> 0.22566827 | J13: 1600000 | K13: 1000 | L13: 18000 | M13: 5000 | N13: =P13*F13*0.5*(1+O13) -> 6.6196026e-05 | O13: 0.1 | P13: 0.03 | Q13: =R13*S13 -> 0.0015735097 | R13: =0.019/1000 -> 1.9e-05 | S13: 82.8163 | T13: =F13+Q13+N13 -> 0.0056515861
A14: AF-DZA | B14: 3.2986825 | C14: 35.271256 | D14: Base | E14: h2 | F14: =(J14*I14)/(L14*M14) -> 0.001588392 | G14: 40 | H14: 0.086058956 | I14: =((1+H14)^G14*H14)/((1+H14)^G14-1) -> 0.08934705 | J14: 1600000 | K14: 1000 | L14: 18000 | M14: 5000 | N14: =P14*F14*0.5*(1+O14) -> 2.6208468e-05 | O14: 0.1 | P14: 0.03 | Q14: =R14*S14 -> 0.0006749389 | R14: =0.019/1000 -> 1.9e-05 | S14: 35.5231 | T14: =F14+Q14+N14 -> 0.0022895394
A15: AF-EGY | B15: 31.216472 | C15: 30.296519 | D15: Base | E15: h2 | F15: =(J15*I15)/(L15*M15) -> 0.0022981056 | G15: 40 | H15: 0.12823197 | I15: =((1+H15)^G15*H15)/((1+H15)^G15-1) -> 0.12926844 | J15: 1600000 | K15: 1000 | L15: 18000 | M15: 5000 | N15: =P15*F15*0.5*(1+O15) -> 3.7918742e-05 | O15: 0.1 | P15: 0.03 | Q15: =R15*S15 -> 0.0006306157 | R15: =0.019/1000 -> 1.9e-05 | S15: 33.1903 | T15: =F15+Q15+N15 -> 0.00296664
A16: AF-ERI | B16: 39.782334 | C16: 15.179384 | D16: Base | E16: h2 | F16: =(J16*I16)/(L16*M16) -> 0.0040118804 | G16: 40 | H16: 0.22560228 | I16: =((1+H16)^G16*H16)/((1+H16)^G16-1) -> 0.22566827 | J16: 1600000 | K16: 1000 | L16: 18000 | M16: 5000 | N16: =P16*F16*0.5*(1+O16) -> 6.6196026e-05 | O16: 0.1 | P16: 0.03 | Q16: =R16*S16 -> 0.0015665975 | R16: =0.019/1000 -> 1.9e-05 | S16: 82.4525 | T16: =F16+Q16+N16 -> 0.0056446739
A17: AF-ESH | B17: -12.885834 | C17: 24.215527 | D17: Base | E17: h2 | F17: =(J17*I17)/(L17*M17) -> 0.0041288829 | G17: 40 | H17: =MAX(H7:H16,H18:H21,H23:H38,H40:H57) -> 0.23219486 | I17: =((1+H17)^G17*H17)/((1+H17)^G17-1) -> 0.23224966 | J17: 1600000 | K17: 1000 | L17: 18000 | M17: 5000 | N17: =P17*F17*0.5*(1+O17) -> 6.8126567e-05 | O17: 0.1 | P17: 0.03 | Q17: =R17*S17 -> 0.0016339069 | R17: =0.019/1000 -> 1.9e-05 | S17: 85.9951 | T17: =F17+Q17+N17 -> 0.0058309163
A18: AF-ETH | B18: 40.489673 | C18: 9.145 | D18: Base | E18: h2 | F18: =(J18*I18)/(L18*M18) -> 0.0024634492 | G18: 40 | H18: 0.13777579 | I18: =((1+H18)^G18*H18)/((1+H18)^G18-1) -> 0.13856902 | J18: 1600000 | K18: 1000 | L18: 18000 | M18: 5000 | N18: =P18*F18*0.5*(1+O18) -> 4.0646912e-05 | O18: 0.1 | P18: 0.03 | Q18: =R18*S18 -> 0.0016339069 | R18: =0.019/1000 -> 1.9e-05 | S18: 85.9951 | T18: =F18+Q18+N18 -> 0.004138003
A19: AF-GAB | B19: 11.609444 | C19: -0.803689 | D19: Base | E19: h2 | F19: =(J19*I19)/(L19*M19) -> 0.0024634492 | G19: 40 | H19: 0.13777579 | I19: =((1+H19)^G19*H19)/((1+H19)^G19-1) -> 0.13856902 | J19: 1600000 | K19: 1000 | L19: 18000 | M19: 5000 | N19: =P19*F19*0.5*(1+O19) -> 4.0646912e-05 | O19: 0.1 | P19: 0.03 | Q19: =R19*S19 -> 0.0015438222 | R19: =0.019/1000 -> 1.9e-05 | S19: 81.2538 | T19: =F19+Q19+N19 -> 0.0040479183
A20: AF-GHA | B20: -1.023194 | C20: 7.946527 | D20: Base | E20: h2 | F20: =(J20*I20)/(L20*M20) -> 0.0026698397 | G20: 40 | H20: 0.14961018 | I20: =((1+H20)^G20*H20)/((1+H20)^G20-1) -> 0.15017848 | J20: 1600000 | K20: 1000 | L20: 18000 | M20: 5000 | N20: =P20*F20*0.5*(1+O20) -> 4.4052355e-05 | O20: 0.1 | P20: 0.03 | Q20: =R20*S20 -> 0.0014871433 | R20: =0.019/1000 -> 1.9e-05 | S20: 78.2707 | T20: =F20+Q20+N20 -> 0.0042010354
A21: AF-GIN | B21: -9.696645 | C21: 9.945587 | D21: Base | E21: h2 | F21: =(J21*I21)/(L21*M21) -> 0.0024940557 | G21: 40 | H21: 0.1395357 | I21: =((1+H21)^G21*H21)/((1+H21)^G21-1) -> 0.14029063 | J21: 1600000 | K21: 1000 | L21: 18000 | M21: 5000 | N21: =P21*F21*0.5*(1+O21) -> 4.1151919e-05 | O21: 0.1 | P21: 0.03 | Q21: =R21*S21 -> 0.0013920806 | R21: =0.019/1000 -> 1.9e-05 | S21: 73.2674 | T21: =F21+Q21+N21 -> 0.0039272882
A22: AF-GMB | B22: -15.310139 | C22: 13.443182 | D22: Base | E22: h2 | F22: =(J22*I22)/(L22*M22) -> 0.0018031123 | G22: 40 | H22: 0.099110374 | I22: =((1+H22)^G22*H22)/((1+H22)^G22-1) -> 0.10142506 | J22: 1600000 | K22: 1000 | L22: 18000 | M22: 5000 | N22: =P22*F22*0.5*(1+O22) -> 2.9751352e-05 | O22: 0.1 | P22: 0.03 | Q22: =R22*S22 -> 0.0013394658 | R22: =0.019/1000 -> 1.9e-05 | S22: 70.4982 | T22: =F22+Q22+N22 -> 0.0031723294
A23: AF-GNB | B23: -15.180413 | C23: 11.803749 | D23: Base | E23: h2 | F23: =(J23*I23)/(L23*M23) -> 0.0021066165 | G23: 40 | H23: 0.11708373 | I23: =((1+H23)^G23*H23)/((1+H23)^G23-1) -> 0.11849718 | J23: 1600000 | K23: 1000 | L23: 18000 | M23: 5000 | N23: =P23*F23*0.5*(1+O23) -> 3.4759172e-05 | O23: 0.1 | P23: 0.03 | Q23: =R23*S23 -> 0.001385176 | R23: =0.019/1000 -> 1.9e-05 | S23: 72.904 | T23: =F23+Q23+N23 -> 0.0035265517
A24: AF-GNQ | B24: 10.267895 | C24: 1.650801 | D24: Base | E24: h2 | F24: =(J24*I24)/(L24*M24) -> 0.0040118804 | G24: 40 | H24: 0.22560228 | I24: =((1+H24)^G24*H24)/((1+H24)^G24-1) -> 0.22566827 | J24: 1600000 | K24: 1000 | L24: 18000 | M24: 5000 | N24: =P24*F24*0.5*(1+O24) -> 6.6196026e-05 | O24: 0.1 | P24: 0.03 | Q24: =R24*S24 -> 0.001536929 | R24: =0.019/1000 -> 1.9e-05 | S24: 80.891 | T24: =F24+Q24+N24 -> 0.0056150054
A25: AF-KEN | B25: 37.906193 | C25: -0.023559 | D25: Base | E25: h2 | F25: =(J25*I25)/(L25*M25) -> 0.0020817976 | G25: 40 | H25: 0.11562961 | I25: =((1+H25)^G25*H25)/((1+H25)^G25-1) -> 0.11710111 | J25: 1600000 | K25: 1000 | L25: 18000 | M25: 5000 | N25: =P25*F25*0.5*(1+O25) -> 3.434966e-05 | O25: 0.1 | P25: 0.03 | Q25: =R25*S25 -> 0.0015755389 | R25: =0.019/1000 -> 1.9e-05 | S25: 82.9231 | T25: =F25+Q25+N25 -> 0.0036916861
A26: AF-LBR | B26: -9.429499 | C26: 6.428055 | D26: Base | E26: h2 | F26: =(J26*I26)/(L26*M26) -> 0.0022603594 | G26: 40 | H26: 0.12604344 | I26: =((1+H26)^G26*H26)/((1+H26)^G26-1) -> 0.12714521 | J26: 1600000 | K26: 1000 | L26: 18000 | M26: 5000 | N26: =P26*F26*0.5*(1+O26) -> 3.729593e-05 | O26: 0.1 | P26: 0.03 | Q26: =R26*S26 -> 0.0014303865 | R26: =0.019/1000 -> 1.9e-05 | S26: 75.2835 | T26: =F26+Q26+N26 -> 0.0037280418
A27: AF-LBY | B27: 16.687794 | C27: 30.664739 | D27: Base | E27: h2 | F27: =(J27*I27)/(L27*M27) -> 0.0013943978 | G27: 40 | H27: 0.073907658 | I27: =((1+H27)^G27*H27)/((1+H27)^G27-1) -> 0.078434879 | J27: 1600000 | K27: 1000 | L27: 18000 | M27: 5000 | N27: =P27*F27*0.5*(1+O27) -> 2.3007564e-05 | O27: 0.1 | P27: 0.03 | Q27: =R27*S27 -> 0.0006530528 | R27: =0.019/1000 -> 1.9e-05 | S27: 34.3712 | T27: =F27+Q27+N27 -> 0.0020704582
A28: AF-LSO | B28: 28.233608 | C28: -29.609988 | D28: Base | E28: h2 | F28: =(J28*I28)/(L28*M28) -> 0.0040118804 | G28: 40 | H28: 0.22560228 | I28: =((1+H28)^G28*H28)/((1+H28)^G28-1) -> 0.22566827 | J28: 1600000 | K28: 1000 | L28: 18000 | M28: 5000 | N28: =P28*F28*0.5*(1+O28) -> 6.6196026e-05 | O28: 0.1 | P28: 0.03 | Q28: =R28*S28 -> 0.0010386426 | R28: =0.019/1000 -> 1.9e-05 | S28: 54.6654 | T28: =F28+Q28+N28 -> 0.005116719
A29: AF-MAR | B29: -6.6901118 | C29: 33.298649 | D29: Base | E29: h2 | F29: =(J29*I29)/(L29*M29) -> 0.0014854775 | G29: 40 | H29: 0.079663627 | I29: =((1+H29)^G29*H29)/((1+H29)^G29-1) -> 0.08355811 | J29: 1600000 | K29: 1000 | L29: 18000 | M29: 5000 | N29: =P29*F29*0.5*(1+O29) -> 2.4510379e-05 | O29: 0.1 | P29: 0.03 | Q29: =R29*S29 -> 0.0007085841 | R29: =0.019/1000 -> 1.9e-05 | S29: 37.2939 | T29: =F29+Q29+N29 -> 0.002218572
... A33: AF-MRT | B33: -10.940835 | C33: 21.00789 | D33: Base | E33: h2 | F33: =(J33*I33)/(L33*M33) -> 0.0040118804 | G33: 40 | H33: 0.22560228 | I33: =((1+H33)^G33*H33)/((1+H33)^G33-1) -> 0.22566827 | J33: 1600000 | K33: 1000 | L33: 18000 | M33: 5000 | N33: =P33*F33*0.5*(1+O33) -> 6.6196026e-05 | O33: 0.1 | P33: 0.03 | Q33: =R33*S33 -> 0.0013446528 | R33: =0.019/1000 -> 1.9e-05 | S33: 70.7712 | T33: =F33+Q33+N33 -> 0.0054227292
A34: AF-MUS | B34: 57.552152 | C34: -20.348404 | D34: Base | E34: h2 | F34: =(J34*I34)/(L34*M34) -> 0.0040118804 | G34: 40 | H34: =MAX($H$2:$H$11,$H$13:$H$16,$H$18:$H$33,$H$35:$H$52) -> 0.22560228 | I34: =((1+H34)^G34*H34)/((1+H34)^G34-1) -> 0.22566827 | J34: 1600000 | K34: 1000 | L34: 18000 | M34: 5000 | N34: =P34*F34*0.5*(1+O34) -> 6.6196026e-05 | O34: 0.1 | P34: 0.03 | Q34: =R34*S34 -> 0.0016339069 | R34: =0.019/1000 -> 1.9e-05 | S34: 85.9951 | T34: =F34+Q34+N34 -> 0.0057119833
A35: AF-MWI | B35: 34.301525 | C35: -13.254308 | D35: Base | E35: h2 | F35: =(J35*I35)/(L35*M35) -> 0.0029273588 | G35: 40 | H35: 0.16428881 | I35: =((1+H35)^G35*H35)/((1+H35)^G35-1) -> 0.16466393 | J35: 1600000 | K35: 1000 | L35: 18000 | M35: 5000 | N35: =P35*F35*0.5*(1+O35) -> 4.830142e-05 | O35: 0.1 | P35: 0.03 | Q35: =R35*S35 -> 0.0011523215 | R35: =0.019/1000 -> 1.9e-05 | S35: 60.6485 | T35: =F35+Q35+N35 -> 0.0041279817
A36: AF-NAM | B36: 18.49041 | C36: -22.95764 | D36: Base | E36: h2 | F36: =(J36*I36)/(L36*M36) -> 0.0017710645 | G36: 40 | H36: 0.097183526 | I36: =((1+H36)^G36*H36)/((1+H36)^G36-1) -> 0.09962238 | J36: 1600000 | K36: 1000 | L36: 18000 | M36: 5000 | N36: =P36*F36*0.5*(1+O36) -> 2.9222565e-05 | O36: 0.1 | P36: 0.03 | Q36: =R36*S36 -> 0.0010683453 | R36: =0.019/1000 -> 1.9e-05 | S36: 56.2287 | T36: =F36+Q36+N36 -> 0.0028686324
A37: AF-NER | B37: 8.081666 | C37: 17.607789 | D37: Base | E37: h2 | F37: =(J37*I37)/(L37*M37) -> 0.0026503445 | G37: 40 | H37: 0.1484954 | I37: =((1+H37)^G37*H37)/((1+H37)^G37-1) -> 0.14908188 | J37: 1600000 | K37: 1000 | L37: 18000 | M37: 5000 | N37: =P37*F37*0.5*(1+O37) -> 4.3730685e-05 | O37: 0.1 | P37: 0.03 | Q37: =R37*S37 -> 0.0010907615 | R37: =0.019/1000 -> 1.9e-05 | S37: 57.4085 | T37: =F37+Q37+N37 -> 0.0037848367
A38: AF-NGA | B38: 8.675277 | C38: 9.081999 | D38: Base | E38: h2 | F38: =(J38*I38)/(L38*M38) -> 0.002233219 | G38: 40 | H38: 0.12446729 | I38: =((1+H38)^G38*H38)/((1+H38)^G38-1) -> 0.12561857 | J38: 1600000 | K38: 1000 | L38: 18000 | M38: 5000 | N38: =P38*F38*0.5*(1+O38) -> 3.6848114e-05 | O38: 0.1 | P38: 0.03 | Q38: =R38*S38 -> 0.0016040332 | R38: =0.019/1000 -> 1.9e-05 | S38: 84.4228 | T38: =F38+Q38+N38 -> 0.0038741003
A39: AF-RWA | B39: 29.873888 | C39: -1.940278 | D39: Base | E39: h2 | F39: =(J39*I39)/(L39*M39) -> 0.0019318924 | G39: 40 | H39: 0.10679194 | I39: =((1+H39)^G39*H39)/((1+H39)^G39-1) -> 0.10866895 | J39: 1600000 | K39: 1000 | L39: 18000 | M39: 5000 | N39: =P39*F39*0.5*(1+O39) -> 3.1876224e-05 | O39: 0.1 | P39: 0.03 | Q39: =R39*S39 -> 0.0015289699 | R39: =0.019/1000 -> 1.9e-05 | S39: 80.4721 | T39: =F39+Q39+N39 -> 0.0034927385
A40: AF-SDN | B40: 30.217636 | C40: 12.862807 | D40: Base | E40: h2 | F40: =(J40*I40)/(L40*M40) -> 0.003877031 | G40: 40 | H40: 0.2180012 | I40: =((1+H40)^G40*H40)/((1+H40)^G40-1) -> 0.21808299 | J40: 1600000 | K40: 1000 | L40: 18000 | M40: 5000 | N40: =P40*F40*0.5*(1+O40) -> 6.3971012e-05 | O40: 0.1 | P40: 0.03 | Q40: =R40*S40 -> 0.0007575015 | R40: =0.019/1000 -> 1.9e-05 | S40: 39.8685 | T40: =F40+Q40+N40 -> 0.0046985035
A41: AF-SEN | B41: -14.452362 | C41: 14.497401 | D41: Base | E41: h2 | F41: =(J41*I41)/(L41*M41) -> 0.0016517703 | G41: 40 | H41: 0.089948372 | I41: =((1+H41)^G41*H41)/((1+H41)^G41-1) -> 0.092912077 | J41: 1600000 | K41: 1000 | L41: 18000 | M41: 5000 | N41: =P41*F41*0.5*(1+O41) -> 2.7254209e-05 | O41: 0.1 | P41: 0.03 | Q41: =R41*S41 -> 0.00134311 | R41: =0.019/1000 -> 1.9e-05 | S41: 70.69 | T41: =F41+Q41+N41 -> 0.0030221345
A42: AF-SLE | B42: -11.779889 | C42: 8.460555 | D42: Base | E42: h2 | F42: =(J42*I42)/(L42*M42) -> 0.002512201 | G42: 40 | H42: 0.14057819 | I42: =((1+H42)^G42*H42)/((1+H42)^G42-1) -> 0.14131131 | J42: 1600000 | K42: 1000 | L42: 18000 | M42: 5000 | N42: =P42*F42*0.5*(1+O42) -> 4.1451317e-05 | O42: 0.1 | P42: 0.03 | Q42: =R42*S42 -> 0.0014047175 | R42: =0.019/1000 -> 1.9e-05 | S42: 73.9325 | T42: =F42+Q42+N42 -> 0.0039583698
A43: AF-SOM | B43: 46.199616 | C43: 5.152149 | D43: Base | E43: h2 | F43: =(J43*I43)/(L43*M43) -> 0.0029647641 | G43: 40 | H43: 0.16641481 | I43: =((1+H43)^G43*H43)/((1+H43)^G43-1) -> 0.16676798 | J43: 1600000 | K43: 1000 | L43: 18000 | M43: 5000 | N43: =P43*F43*0.5*(1+O43) -> 4.8918608e-05 | O43: 0.1 | P43: 0.03 | Q43: =R43*S43 -> 0.0014560669 | R43: =0.019/1000 -> 1.9e-05 | S43: 76.6351 | T43: =F43+Q43+N43 -> 0.0044697496
...

Sheet shipping_collection
A1: Overall info
A2: Lower Heating Values (LHV) | B2: VLSFO | C2: MWh/t | D2: 11.2 | E2: =(F2+D2)/2 -> 11.5 | F2: 11.8
B3: MGO | C3: MWh/t | D3: =42.7/3.6 -> 11.861111 | E3: =(F3+D3)/2 -> 11.902778 | F3: =43/3600*1000 -> 11.944444 | H3: https://www.researchgate.net/publication/305438099_Forecasting_port-level_demand_for_LNG_as_a_ship_fuel_the_case_of_the_port_of_Antwerp
B4: IFO380 | C4: MWh/t | D4: 11.22 | E4: =(F4+D4)/2 -> 11.415 | F4: 11.61 | H4: https://bunkerindex.com/help/article.php?a=21678&h=lng-price-conversion
B5: HFO | C5: MWh/t | D5: =38.3/3.6 -> 10.638889 | E5: =(F5+D5)/2 -> 10.930556 | F5: =40.4/3600*1000 -> 11.222222 | H5: https://www.researchgate.net/publication/305438099_Forecasting_port-level_demand_for_LNG_as_a_ship_fuel_the_case_of_the_port_of_Antwerp
B6: LNG | C6: MWh/t | D6: =48/3600*1000 -> 13.333333 | E6: =(F6+D6)/2 -> 13.472222 | F6: =49/3600*1000 -> 13.611111 | H6: https://www.researchgate.net/publication/305438099_Forecasting_port-level_demand_for_LNG_as_a_ship_fuel_the_case_of_the_port_of_Antwerp
A7: Energy denstiy | B7: H2 (liq) | C7: MWh/t | D7: 33.33 | E7: MWh/m³ | F7: 2.3 | G7: ="-253°C" -> -253°C | H7: https://www.wasserstoff-leitprojekte.de/lw_resource/datapool/systemfiles/elements/files/F4941D1CBA383928E0537E695E862E63/live/document/Wasserstoff-Verfl%C3%BCssigung,_Speicherung,_Transport_und_Anwendung_von_fl%C3%BCssigem_Wasserstoff__2_.pdf | O7: Literature Value | P7: Chosen value
A8: Energy denstiy | B8: H2 | C8: MWh/t | D8: 33.33 | E8: MWh/m³ | F8: 1.4 | G8: 700 bar | H8: https://www.wasserstoff-leitprojekte.de/lw_resource/datapool/systemfiles/elements/files/F4941D1CBA383928E0537E695E862E63/live/document/Wasserstoff-Verfl%C3%BCssigung,_Speicherung,_Transport_und_Anwendung_von_fl%C3%BCssigem_Wasserstoff__2_.pdf | O8: Calculated Value | P8: Chosen value
A9: Energy denstiy | B9: NH3 (liq) | C9: MWh/t | D9: 5.2 | E9: MWh/m³ | F9: 3.6 | H9: https://www.wasserstoff-leitprojekte.de/lw_resource/datapool/systemfiles/elements/files/F4941D1CBA383928E0537E695E862E63/live/document/Wasserstoff-Verfl%C3%BCssigung,_Speicherung,_Transport_und_Anwendung_von_fl%C3%BCssigem_Wasserstoff__2_.pdf | O9: Expert assumption | P9: Chosen value
A10: Energy denstiy | B10: MeOH (liq) | C10: MWh/t | D10: 5.5 | E10: MWh/m³ | F10: 4.4 | O10: AI value | P10: Chosen value
A11: Energy denstiy | B11: SNG | C11: MWh/t | D11: 13.9 | E11: MWh/m³ | F11: 6.6
A12: Energy denstiy | B12: Diesel | C12: MWh/t | D12: 11.9 | E12: MWh/m³ | F12: 9.8 | H12: https://www.wasserstoff-leitprojekte.de/lw_resource/datapool/systemfiles/elements/files/F4941D1CBA383928E0537E695E862E63/live/document/Wasserstoff-Verfl%C3%BCssigung,_Speicherung,_Transport_und_Anwendung_von_fl%C3%BCssigem_Wasserstoff__2_.pdf
A13: Conversion rate | C13: €/$ | D13: 0.88
A14: ETS | B14: 2040 | C14: €/tCo2 | D14: 150 | E14: APS_2040 | F14: https://oa.tib.eu/renate/items/34717383-7179-419d-800d-8a15eff7febb
A15: emission_factor | C15: tCo2/tfuel | D15: =3206/1000 -> 3.206 | E15: =3114/1000 -> 3.114 | F15: https://www.climatiq.io/data/emission-factor/4ee1a3af-8ba4-46a8-9d3c-6198f4e1cc05
C16: tCo2/MWh_fuel | D16: =D15/E2 -> 0.27878261 | E16: =E15/E2 -> 0.27078261
C17: tCo2/TJ | D17: =(79+81.3)/2 -> 80.15 | E17: tCo2/MWh_fuel | F17: =D17/277.78 -> 0.28853769 | G17: CO2 Emission Factors for Fossil Fuels (umweltbundesamt.de)
A18: fuel_costs
A19: VLSFO diesel | B19: 2024 | C19: $/t | D19: 630 | E19: €/MWh_fuel | F19: =D19/E2*D13 -> 48.208696
B20: 2025 | C20: $/t | D20: 585 | E20: €/MWh_fuel | F20: =D20/$E$2*$D$13 -> 44.765217 | AJ20: https://www.sdewes.org/jsdewes/pid12.0484
B21: 2026 | D21: =D34 -> 780.25 | F21: =D21/$E$2*$D$13 -> 59.706087 | AJ21: Radosits et al
A22: Fuel cost Santos | B22: 2022 | C22: €/t_fuel | D22: =682*0.86 -> 586.52 | E22: €/MWh_fuel | F22: =D22/E2 -> 51.001739 | G22: World Bunker Prices - Ship & Bunker (shipandbunker.com)
A23: Fuel cost Rotterdam | B23: 2022 | C23: €/t_fuel | D23: =0.86*638.5 -> 549.11 | E23: €/MWh_fuel | F23: =D23/E2 -> 47.748696 | G23: World Bunker Prices - Ship & Bunker (shipandbunker.com)
A25: fuel_costs_global | B25: Year | D25: VLSFO | E25: MGO | F25: IFO380 | H25: VLSFO | I25: MGO | J25: IFO380
A26: LA/Long Beach | B26: 2026 | C26: $/t | D26: 810 | E26: 1365 | F26: 678 | G26: €/MWh_fuel | H26: =D26*$D$13/$E$2 -> 61.982609 | I26: =E26*$D$13/$E$2 -> 104.45217 | J26: =F26*$D$13/$E$2 -> 51.881739 | K26: World Bunker Prices - Ship & Bunker (shipandbunker.com) | L26: 46237
A27: New York | B27: 2026 | C27: $/t | D27: 724 | E27: 1348 | F27: 540 | G27: €/MWh_fuel | H27: =D27*$D$13/$E$2 -> 55.401739 | I27: =E27*$D$13/$E$2 -> 103.1513 | J27: =F27*$D$13/$E$2 -> 41.321739 | K27: World Bunker Prices - Ship & Bunker (shipandbunker.com) | L27: 46237
A28: Houston | B28: 2026 | C28: $/t | D28: 734 | E28: 1241 | F28: 487 | G28: €/MWh_fuel | H28: =D28*$D$13/$E$2 -> 56.166957 | I28: =E28*$D$13/$E$2 -> 94.963478 | J28: =F28*$D$13/$E$2 -> 37.266087 | K28: World Bunker Prices - Ship & Bunker (shipandbunker.com) | L28: 46237 | Y28: https://www.belfercenter.org/sites/default/files/pantheon_files/files/publication/Report_EU%20Hydrogen_FINAL.pdf
A29: Santos | B29: 2026 | C29: $/t | D29: 815 | E29: 1286 | F29: 511 | G29: €/MWh_fuel | H29: =D29*$D$13/$E$2 -> 62.365217 | I29: =E29*$D$13/$E$2 -> 98.406957 | J29: =F29*$D$13/$E$2 -> 39.102609 | K29: World Bunker Prices - Ship & Bunker (shipandbunker.com) | L29: 46237
A30: Rotterdam | B30: 2026 | C30: $/t | D30: 679 | E30: 1282 | F30: 529 | G30: €/MWh_fuel | H30: =D30*$D$13/$E$2 -> 51.958261 | I30: =E30*$D$13/$E$2 -> 98.10087 | J30: =F30*$D$13/$E$2 -> 40.48 | K30: World Bunker Prices - Ship & Bunker (shipandbunker.com) | L30: 46237
A31: Fujairah | B31: 2026 | C31: $/t | D31: 809 | E31: 1283 | F31: 598 | G31: €/MWh_fuel | H31: =D31*$D$13/$E$2 -> 61.906087 | I31: =E31*$D$13/$E$2 -> 98.177391 | J31: =F31*$D$13/$E$2 -> 45.76 | K31: World Bunker Prices - Ship & Bunker (shipandbunker.com) | L31: 46237
A32: Hong Kong | B32: 2026 | C32: $/t | D32: 833 | E32: 1226 | F32: 623 | G32: €/MWh_fuel | H32: =D32*$D$13/$E$2 -> 63.742609 | I32: =E32*$D$13/$E$2 -> 93.815652 | J32: =F32*$D$13/$E$2 -> 47.673043 | K32: World Bunker Prices - Ship & Bunker (shipandbunker.com) | L32: 46237 | T32: Benchmark Values from Claude
A33: Singapore | B33: 2026 | C33: $/t | D33: 838 | E33: 1226 | F33: 582 | G33: €/MWh_fuel | H33: =D33*$D$13/$E$2 -> 64.125217 | I33: =E33*$D$13/$E$2 -> 93.815652 | J33: =F33*$D$13/$E$2 -> 44.535652 | K33: World Bunker Prices - Ship & Bunker (shipandbunker.com) | L33: 46237
A34: Mean | B34: 2026 | C34: $/t | D34: =AVERAGE(D26:D33) -> 780.25 | E34: =AVERAGE(E26:E33) -> 1282.125 | F34: =AVERAGE(F26:F33) -> 568.5 | G34: €/MWh_fuel | H34: =D34*$D$13/$E$2 -> 59.706087 | I34: =E34*$D$13/$E$2 -> 98.110435 | J34: =F34*$D$13/$E$2 -> 43.502609 | AJ34: https://pdf.sciencedirectassets.com/271472/1-s2.0-S0360319925X00422/1-s2.0-S0360319925012182/main.pdf?X-Amz-Security-Token=IQoJb3JpZ2luX2VjEJD%2F%2F%2F%2F%2F%2F%2F%2F%2F%2FwEaCXVzLWVhc3QtMSJHMEUCIEnsTTcsFowhwLMtYgKYySQzvwOR1LgVWZL4VWq7roAGAiEAy2vQuPGXGs6jSmbA7wK%2FUnpxwFZJ5a5nz0mRyCO2U%2FsqsgUIWBAFGgwwNTkwMDM1NDY4NjUiDDb6vN%2Fm2E9qYf3XdSqPBXPRX4tS1Ejwb12zgy6Z61yG0M1dBYhxACu3%2FqRL%2FMqiCeUO657Hz59TsnddCOTlxz9CBvjstrFjNaN9%2F24J8n3kyfzqdvYmeAIgolT12cQQqbBbZ2%2BEo0FHHsoOQG3mbJY0R2VUDc%2FZWcwjP723i0Vp6zKCNgsNielYuICzXQi8lD27u%2BOuLSjP%2BNg6uNeLnpbVOdI2pVal2xCkJ%2BtubXdvLcrAUtQi1WKOKjSCIlKL%2FtU90UcGIJhyVJaFv03oVL4MZZbf058mAbS53BNCByQz14O%2FMiJUAbQT8BqUyOpogip6aK2XotIoh7bmX%2BmF%2FJ%2F2ylM9thpMBcWDtJl2l5QO7ZRr5r77X8ndpzaKLOKA8KXRsqe7hBTs9HXULUZ%2Fw6Vw4QKUmLj9NTAuXf%2BM5fMlqojeAaIUnIPNjDQmH9LAQPT3tTzkXHPDU%2B7TIDx7KLF%2F3YKheHlO1%2BD0969U%2B7atF8k9Fe2ykLTIS6lq3ND5%2F6Lev4ZCRNnO%2Btg5f1Z%2BMErv8jpIThMt7vayjSgu3QtJ7%2BnDl1zzGGdEKBPeUZmjbFsHBeau4F6O8V7TP8TsBW9jcIaegyIGj7kxRbh0jQPeylbSsKs42dpxOGF1NfUDdxk2VfiLnjZZ%2FQD1O%2BwVPK8qduOnNecaeEBqN2InmSNjnZRg0ZHd5%2FEy5FHaN3SB2qcu33UDh2xZrCWh2R3uWYFh3F2eDf5hrDHjMX7kUvEHfwCRTTW8ZSZp7eKHbJ9TOM87DwHoD5j2N0MTKTC482mJdKSb6xqEMOwHhkiARKYS5KiUFE4CxSmOUk%2FtA1FLNe%2BjE8o0yW98TA%2BPLp2%2FHd%2FBJYDhbG5vHDPxD0lUovcey19wRbU72UZyT%2BCFQ84w9KrI1AY6sQGHjWPcZ6xQj4CrBBfQKgfI7sD4IlP0sBvIPB1B9xvcCLY9NH3dZjh51OdhJeDmxMeD1028aUpTQM85CRytfDAsR%2BIgep8%2Bzmih55w2%2BjI0i5xOWguPwCfvx96jP0cKxnYNd0Od%2F4A9kDPG%2Ff%2FLhEhe8tuVyKqV4e7cfZSvdQjHmDVLaSi3xvGVXp9J%2F7VBd4z%2BvtFdIuA%2FL9VyEdxvrsHJ%2B0iF4NMCFoo%2B9jfdTGoF21E%3D&X-Amz-Algorithm=AWS4-HMAC-SHA256&X-Amz-Date=20260828T232331Z&X-Amz-SignedHeaders=host&X-Amz-Expires=300&X-Amz-Credential=ASIAQ3PHCVTYYACVTZLZ%2F20260828%2Fus-east-1%2Fs3%2Faws4_request&X-Amz-Signature=c05af2d880e4a512daa064ba8c49c7f6f176dfdfdf964a52edd9cd5e8f868fc1&hash=cc12c021dcd96e1b1054e5e13c8f7428c3a84081beae9b3f3c4413f3fa1881a2&host=68042c943591013ac2b2430a89b270f6af2c76d8dfd086a07176afe7c76c2c61&pii=S0360319925012182&tid=spdf-58f8da29-096c-41e5-8aa5-d3c2465a442f&sid=0d4591e34b5b4741081b46a3b13fd5c0c635gxrqb&type=client&tsoh=d3d3LnNjaWVuY2VkaXJlY3QuY29t&rh=d3d3LnNjaWVuY2VkaXJlY3QuY29t&ua=011105505c54575153&rr=a32710719d958804&cc=es
AJ35: Onat & Demir
A36: fuel_costs incl Co2 price | B36: 2026 | C36: €/MWh | D36: =$H$34+$F$17*$D$14 -> 102.98674 | AV36: 0.0378 | AW36: kWh/kgNH3
AV37: =AV36/D9 -> 0.0072692308 | AW37: kWh_el/kWhNH3
A38: Susio Frontier | B38: kn | C38: 13 | D38: World's 1st LH2 carrier Suiso Frontier departs for Australia - Offshore Energy (offshore-energy.biz) | AV38: =1-AV37 -> 0.99273077 | AW38: % energetic efficiency
B39: kn | C39: 30 | D39: IEA The future of hydrogen assumptions
A40: tanker capacity | C40: payload min | D40: payload mean | E40: payload max | G40: payload min | H40: payload mean | I40: payload max
A41: small | B41: m³ | C41: 5000 | D41: =(E41+C41)/2 -> 12500 | E41: 20000 | F41: MWh_h2liq | G41: =C41*$F$7 -> 11500 | H41: =D41*$F$7 -> 28750 | I41: =E41*$F$7 -> 46000 | J41: MWh_nh3 | K41: =C41*$F$9 -> 18000 | L41: =D41*$F$9 -> 45000 | M41: =E41*$F$9 -> 72000 | N41: MWh_MeOH | O41: =C41*$F$10 -> 22000 | P41: =D41*$F$10 -> 55000 | Q41: =E41*$F$10 -> 88000
...

Sheet shipping_compact
D1: invest_cost | E1: full_load_hours | F1: lifetime | G1: efficiency_substantial | H1: efficiency_energetic | I1: efficiency_dynamic | J1: fom_factor | K1: electricity_consumption | L1: fuel_consumption
A2: transport_commodity | B2: process | C2: generalisation | D2: €/MW | E2: h/a | F2: a | G2: - | H2: - | I2: %/km | J2: %/invest_cost | K2: MWh_el/MWh_x | L2: MWh_fuel/MWh_x
A3: h2liq | B3: Liquefaction | C3: Conversion | D3: 938550 | E3: 6000 | F3: 30 | G3: 0.98 | H3: 0.7449745 | J3: 0.0325 | K3: 0 | N3: final values
A4: h2liq | B4: Port Storage
A5: h2liq | B5: Export Terminal
A6: h2liq | B6: Import Terminal
A7: h2liq | C7: Terminal | D7: 14340589 | E7: 6000 | F7: 30 | G7: 1 | H7: 1 | J7: 0.04 | K7: 0
A8: h2liq | C8: Shipping | D8: 144364800 | E8: 4380 | F8: 25 | G8: 0.987 | H8: 1 | I8: =0.002/720 -> 2.7777778e-06 | J8: 0.04 | L8: 0.00034594341
A9: h2liq | B9: Regasification | C9: Reconversion | D9: 226010 | E9: 6000 | F9: 30 | G9: 0.98 | H9: 0.98 | J9: 0.03 | K9: 0.0060006001
A10: nh3 | B10: ASU | D10: 4143791 | G10: 1 | J10: 0.03 | K10: 0.0399
A11: nh3 | B11: Haber_Bosch | D11: 1842989 | G11: 0.99 | H11: 0.871 | J11: 0.03 | K11: 0.2473
A12: nh3 | B12: Synthesis | C12: Conversion | D12: =SUM(D10:D11) -> 5986780 | E12: 6000 | F12: 30 | G12: 0.85 | H12: 0.992 | J12: 0.05 | K12: =SUM(K10:K11) -> 0.2872
A13: nh3 | B13: Port Storage
A14: nh3 | B14: Export Terminal
A15: nh3 | B15: Import Terminal
A16: nh3 | C16: Terminal | D16: 293456.89 | E16: 6000 | F16: 30 | G16: 1 | H16: 1 | J16: 0.04 | K16: 0
A17: nh3 | C17: Shipping | D17: 6181584.9 | E17: 4380 | F17: 25 | G17: 1 | H17: 1 | I17: 0 | J17: 0.04 | L17: 0.0002210194
A18: nh3 | B18: Cracking | C18: Reconversion | D18: 1418767 | E18: 6000 | F18: 30 | G18: 0.996 | H18: 0.685 | J18: 0.043 | K18: 0
A19: ch3oh | B19: Methanation | D19: 3500000 | G19: 0.75
A20: ch3oh | B20: Methanolsation | D20: 3800000 | G20: 0.79
A21: ch3oh | B21: Synthesis | C21: Conversion | D21: =SUM(D19:D20) -> 7300000 | E21: 6000 | F21: 30 | G21: =G20*G19 -> 0.5925 | H21: 1 | J21: 0.04
A22: ch3oh | B22: Port Storage
A23: ch3oh | B23: Export Terminal
A24: ch3oh | B24: Import Terminal
A25: ch3oh | C25: Terminal | D25: =D16 -> 293456.89 | E25: 6000 | F25: 30 | G25: 1 | H25: 1 | J25: 0.04 | K25: 0.271
A26: ch3oh | C26: Shipping | D26: 1756697 | E26: 4380 | F26: 25 | G26: 1 | H26: 1 | I26: 0 | J26: 0.04 | L26: 0.00018083405
A27: ch3oh | B27: Cracking | C27: Reconversion | D27: 22653 | E27: 6000 | F27: 30 | G27: 0.99 | H27: 0.833 | J27: 0.04 | K27: 0

Sheet shipping_data
A1: terminal_name | B1: commodity | C1: name | D1: node | E1: lat | F1: lon | G1: alternative | H1: conversion_invest_cost | I1: full_load_hours | J1: conversion_lifetime | K1: conversion_efficiency_substantial | L1: conversion_efficiency_energetic | M1: conversion_fom_capex_factor | N1: electricity_per_energy_converted | O1: terminal_invest_cost | P1: terminal_lifetime | Q1: terminal_efficiency | R1: terminal_fom_capex_factor | S1: electricity_per_energy_loaded | T1: shipping_invest_cost | U1: shipping_full_load_hours | V1: shipping_lifetime | W1: shipping_efficiency_flat | X1: shipping_efficiency_km | Y1: shipping_fom_capex_factor | Z1: fuel_consumption_km | AA1: reconversion_invest_cost | AB1: reconversion_lifetime | AC1: reconversion_efficiency_substantial | AD1: reconversion_efficiency_energetic | AE1: reconversion_fom_capex_factor | AF1: electricity_per_energy_reconverted
A2: terminal_EU-NLD | B2: h2liq | C2: =_xlfn.CONCAT(B2,"_",A2) -> h2liq_terminal_EU-NLD | D2: EU-NLD | E2: 51.948455 | F2: 4.140296 | G2: Base | H2: =shipping_compact!D$3 -> 938550 | I2: =shipping_compact!E$3 -> 6000 | J2: =shipping_compact!F$3 -> 30 | K2: =shipping_compact!G$3 -> 0.98 | L2: =shipping_compact!H$3 -> 0.7449745 | M2: =shipping_compact!J$3 -> 0.0325 | N2: =shipping_compact!K$3 -> 0 | O2: =shipping_compact!D$7 -> 14340589 | P2: =shipping_compact!F$7 -> 30 | Q2: =shipping_compact!G$7 -> 1 | R2: =shipping_compact!J$7 -> 0.04 | S2: =shipping_compact!L$7 -> 0 | T2: =shipping_compact!D$8 -> 144364800 | U2: =shipping_compact!E$8 -> 4380 | V2: =shipping_compact!F$8 -> 25 | W2: =shipping_compact!G$8 -> 0.987 | X2: =shipping_compact!I$8 -> 2.7777778e-06 | Y2: =shipping_compact!J$8 -> 0.04 | Z2: =shipping_compact!L$8 -> 0.00034594341 | AA2: =shipping_compact!D$9 -> 226010 | AB2: =shipping_compact!F$9 -> 30 | AC2: =shipping_compact!G$9 -> 0.98 | AD2: =shipping_compact!H$9 -> 0.98 | AE2: =shipping_compact!J$9 -> 0.03 | AF2: =shipping_compact!K$9 -> 0.0060006001
A3: terminal_EU-PRT | B3: h2liq | C3: =_xlfn.CONCAT(B3,"_",A3) -> h2liq_terminal_EU-PRT | D3: EU-PRT | E3: 37.961098 | F3: -8.8786877 | G3: Base | H3: =shipping_compact!$D$3 -> 938550 | I3: =shipping_compact!E$3 -> 6000 | J3: =shipping_compact!F$3 -> 30 | K3: =shipping_compact!G$3 -> 0.98 | L3: =shipping_compact!H$3 -> 0.7449745 | M3: =shipping_compact!J$3 -> 0.0325 | N3: =shipping_compact!K$3 -> 0 | O3: =shipping_compact!D$7 -> 14340589 | P3: =shipping_compact!F$7 -> 30 | Q3: =shipping_compact!G$7 -> 1 | R3: =shipping_compact!J$7 -> 0.04 | S3: =shipping_compact!L$7 -> 0 | T3: =shipping_compact!D$8 -> 144364800 | U3: =shipping_compact!E$8 -> 4380 | V3: =shipping_compact!F$8 -> 25 | W3: =shipping_compact!G$8 -> 0.987 | X3: =shipping_compact!I$8 -> 2.7777778e-06 | Y3: =shipping_compact!J$8 -> 0.04 | Z3: =shipping_compact!L$8 -> 0.00034594341 | AA3: =shipping_compact!D$9 -> 226010 | AB3: =shipping_compact!F$9 -> 30 | AC3: =shipping_compact!G$9 -> 0.98 | AD3: =shipping_compact!H$9 -> 0.98 | AE3: =shipping_compact!J$9 -> 0.03 | AF3: =shipping_compact!K$9 -> 0.0060006001
A4: terminal_EU-ESP | B4: h2liq | C4: =_xlfn.CONCAT(B4,"_",A4) -> h2liq_terminal_EU-ESP | D4: EU-ESP | E4: 39.463713 | F4: -0.35881979 | G4: Base | H4: =shipping_compact!$D$3 -> 938550 | I4: =shipping_compact!E$3 -> 6000 | J4: =shipping_compact!F$3 -> 30 | K4: =shipping_compact!G$3 -> 0.98 | L4: =shipping_compact!H$3 -> 0.7449745 | M4: =shipping_compact!J$3 -> 0.0325 | N4: =shipping_compact!K$3 -> 0 | O4: =shipping_compact!D$7 -> 14340589 | P4: =shipping_compact!F$7 -> 30 | Q4: =shipping_compact!G$7 -> 1 | R4: =shipping_compact!J$7 -> 0.04 | S4: =shipping_compact!L$7 -> 0 | T4: =shipping_compact!D$8 -> 144364800 | U4: =shipping_compact!E$8 -> 4380 | V4: =shipping_compact!F$8 -> 25 | W4: =shipping_compact!G$8 -> 0.987 | X4: =shipping_compact!I$8 -> 2.7777778e-06 | Y4: =shipping_compact!J$8 -> 0.04 | Z4: =shipping_compact!L$8 -> 0.00034594341 | AA4: =shipping_compact!D$9 -> 226010 | AB4: =shipping_compact!F$9 -> 30 | AC4: =shipping_compact!G$9 -> 0.98 | AD4: =shipping_compact!H$9 -> 0.98 | AE4: =shipping_compact!J$9 -> 0.03 | AF4: =shipping_compact!K$9 -> 0.0060006001
A5: terminal_EU-ISL | B5: h2liq | C5: =_xlfn.CONCAT(B5,"_",A5) -> h2liq_terminal_EU-ISL | D5: EU-ISL | E5: 64.094858 | F5: -21.853528 | G5: Base | H5: =shipping_compact!$D$3 -> 938550 | I5: =shipping_compact!E$3 -> 6000 | J5: =shipping_compact!F$3 -> 30 | K5: =shipping_compact!G$3 -> 0.98 | L5: =shipping_compact!H$3 -> 0.7449745 | M5: =shipping_compact!J$3 -> 0.0325 | N5: =shipping_compact!K$3 -> 0 | O5: =shipping_compact!D$7 -> 14340589 | P5: =shipping_compact!F$7 -> 30 | Q5: =shipping_compact!G$7 -> 1 | R5: =shipping_compact!J$7 -> 0.04 | S5: =shipping_compact!L$7 -> 0 | T5: =shipping_compact!D$8 -> 144364800 | U5: =shipping_compact!E$8 -> 4380 | V5: =shipping_compact!F$8 -> 25 | W5: =shipping_compact!G$8 -> 0.987 | X5: =shipping_compact!I$8 -> 2.7777778e-06 | Y5: =shipping_compact!J$8 -> 0.04 | Z5: =shipping_compact!L$8 -> 0.00034594341 | AA5: =shipping_compact!D$9 -> 226010 | AB5: =shipping_compact!F$9 -> 30 | AC5: =shipping_compact!G$9 -> 0.98 | AD5: =shipping_compact!H$9 -> 0.98 | AE5: =shipping_compact!J$9 -> 0.03 | AF5: =shipping_compact!K$9 -> 0.0060006001
A6: terminal_EU-ITA4 | B6: h2liq | C6: =_xlfn.CONCAT(B6,"_",A6) -> h2liq_terminal_EU-ITA4 | D6: EU-ITA4 | E6: 45.205817 | F6: 12.293656 | G6: Base | H6: =shipping_compact!$D$3 -> 938550 | I6: =shipping_compact!E$3 -> 6000 | J6: =shipping_compact!F$3 -> 30 | K6: =shipping_compact!G$3 -> 0.98 | L6: =shipping_compact!H$3 -> 0.7449745 | M6: =shipping_compact!J$3 -> 0.0325 | N6: =shipping_compact!K$3 -> 0 | O6: =shipping_compact!D$7 -> 14340589 | P6: =shipping_compact!F$7 -> 30 | Q6: =shipping_compact!G$7 -> 1 | R6: =shipping_compact!J$7 -> 0.04 | S6: =shipping_compact!L$7 -> 0 | T6: =shipping_compact!D$8 -> 144364800 | U6: =shipping_compact!E$8 -> 4380 | V6: =shipping_compact!F$8 -> 25 | W6: =shipping_compact!G$8 -> 0.987 | X6: =shipping_compact!I$8 -> 2.7777778e-06 | Y6: =shipping_compact!J$8 -> 0.04 | Z6: =shipping_compact!L$8 -> 0.00034594341 | AA6: =shipping_compact!D$9 -> 226010 | AB6: =shipping_compact!F$9 -> 30 | AC6: =shipping_compact!G$9 -> 0.98 | AD6: =shipping_compact!H$9 -> 0.98 | AE6: =shipping_compact!J$9 -> 0.03 | AF6: =shipping_compact!K$9 -> 0.0060006001
A7: terminal_EU-ITA | B7: h2liq | C7: =_xlfn.CONCAT(B7,"_",A7) -> h2liq_terminal_EU-ITA | D7: EU-ITA | E7: 45.205817 | F7: 12.293656 | G7: Base | H7: =shipping_compact!$D$3 -> 938550 | I7: =shipping_compact!E$3 -> 6000 | J7: =shipping_compact!F$3 -> 30 | K7: =shipping_compact!G$3 -> 0.98 | L7: =shipping_compact!H$3 -> 0.7449745 | M7: =shipping_compact!J$3 -> 0.0325 | N7: =shipping_compact!K$3 -> 0 | O7: =shipping_compact!D$7 -> 14340589 | P7: =shipping_compact!F$7 -> 30 | Q7: =shipping_compact!G$7 -> 1 | R7: =shipping_compact!J$7 -> 0.04 | S7: =shipping_compact!L$7 -> 0 | T7: =shipping_compact!D$8 -> 144364800 | U7: =shipping_compact!E$8 -> 4380 | V7: =shipping_compact!F$8 -> 25 | W7: =shipping_compact!G$8 -> 0.987 | X7: =shipping_compact!I$8 -> 2.7777778e-06 | Y7: =shipping_compact!J$8 -> 0.04 | Z7: =shipping_compact!L$8 -> 0.00034594341 | AA7: =shipping_compact!D$9 -> 226010 | AB7: =shipping_compact!F$9 -> 30 | AC7: =shipping_compact!G$9 -> 0.98 | AD7: =shipping_compact!H$9 -> 0.98 | AE7: =shipping_compact!J$9 -> 0.03 | AF7: =shipping_compact!K$9 -> 0.0060006001
A8: terminal_AS-TUR | B8: h2liq | C8: =_xlfn.CONCAT(B8,"_",A8) -> h2liq_terminal_AS-TUR | D8: AS-TUR | E8: 36.825941 | F8: 36.177898 | G8: Base | H8: =shipping_compact!$D$3 -> 938550 | I8: =shipping_compact!E$3 -> 6000 | J8: =shipping_compact!F$3 -> 30 | K8: =shipping_compact!G$3 -> 0.98 | L8: =shipping_compact!H$3 -> 0.7449745 | M8: =shipping_compact!J$3 -> 0.0325 | N8: =shipping_compact!K$3 -> 0 | O8: =shipping_compact!D$7 -> 14340589 | P8: =shipping_compact!F$7 -> 30 | Q8: =shipping_compact!G$7 -> 1 | R8: =shipping_compact!J$7 -> 0.04 | S8: =shipping_compact!L$7 -> 0 | T8: =shipping_compact!D$8 -> 144364800 | U8: =shipping_compact!E$8 -> 4380 | V8: =shipping_compact!F$8 -> 25 | W8: =shipping_compact!G$8 -> 0.987 | X8: =shipping_compact!I$8 -> 2.7777778e-06 | Y8: =shipping_compact!J$8 -> 0.04 | Z8: =shipping_compact!L$8 -> 0.00034594341 | AA8: =shipping_compact!D$9 -> 226010 | AB8: =shipping_compact!F$9 -> 30 | AC8: =shipping_compact!G$9 -> 0.98 | AD8: =shipping_compact!H$9 -> 0.98 | AE8: =shipping_compact!J$9 -> 0.03 | AF8: =shipping_compact!K$9 -> 0.0060006001
A9: terminal_EU-SWE3 | B9: h2liq | C9: =_xlfn.CONCAT(B9,"_",A9) -> h2liq_terminal_EU-SWE3 | D9: EU-SWE3 | E9: 58.913025 | F9: 17.96051 | G9: Base | H9: =shipping_compact!$D$3 -> 938550 | I9: =shipping_compact!E$3 -> 6000 | J9: =shipping_compact!F$3 -> 30 | K9: =shipping_compact!G$3 -> 0.98 | L9: =shipping_compact!H$3 -> 0.7449745 | M9: =shipping_compact!J$3 -> 0.0325 | N9: =shipping_compact!K$3 -> 0 | O9: =shipping_compact!D$7 -> 14340589 | P9: =shipping_compact!F$7 -> 30 | Q9: =shipping_compact!G$7 -> 1 | R9: =shipping_compact!J$7 -> 0.04 | S9: =shipping_compact!L$7 -> 0 | T9: =shipping_compact!D$8 -> 144364800 | U9: =shipping_compact!E$8 -> 4380 | V9: =shipping_compact!F$8 -> 25 | W9: =shipping_compact!G$8 -> 0.987 | X9: =shipping_compact!I$8 -> 2.7777778e-06 | Y9: =shipping_compact!J$8 -> 0.04 | Z9: =shipping_compact!L$8 -> 0.00034594341 | AA9: =shipping_compact!D$9 -> 226010 | AB9: =shipping_compact!F$9 -> 30 | AC9: =shipping_compact!G$9 -> 0.98 | AD9: =shipping_compact!H$9 -> 0.98 | AE9: =shipping_compact!J$9 -> 0.03 | AF9: =shipping_compact!K$9 -> 0.0060006001
A10: terminal_EU-SWE | B10: h2liq | C10: =_xlfn.CONCAT(B10,"_",A10) -> h2liq_terminal_EU-SWE | D10: EU-SWE | E10: 58.913025 | F10: 17.96051 | G10: Base | H10: =shipping_compact!$D$3 -> 938550 | I10: =shipping_compact!E$3 -> 6000 | J10: =shipping_compact!F$3 -> 30 | K10: =shipping_compact!G$3 -> 0.98 | L10: =shipping_compact!H$3 -> 0.7449745 | M10: =shipping_compact!J$3 -> 0.0325 | N10: =shipping_compact!K$3 -> 0 | O10: =shipping_compact!D$7 -> 14340589 | P10: =shipping_compact!F$7 -> 30 | Q10: =shipping_compact!G$7 -> 1 | R10: =shipping_compact!J$7 -> 0.04 | S10: =shipping_compact!L$7 -> 0 | T10: =shipping_compact!D$8 -> 144364800 | U10: =shipping_compact!E$8 -> 4380 | V10: =shipping_compact!F$8 -> 25 | W10: =shipping_compact!G$8 -> 0.987 | X10: =shipping_compact!I$8 -> 2.7777778e-06 | Y10: =shipping_compact!J$8 -> 0.04 | Z10: =shipping_compact!L$8 -> 0.00034594341 | AA10: =shipping_compact!D$9 -> 226010 | AB10: =shipping_compact!F$9 -> 30 | AC10: =shipping_compact!G$9 -> 0.98 | AD10: =shipping_compact!H$9 -> 0.98 | AE10: =shipping_compact!J$9 -> 0.03 | AF10: =shipping_compact!K$9 -> 0.0060006001
A11: terminal_EU-GBR | B11: h2liq | C11: =_xlfn.CONCAT(B11,"_",A11) -> h2liq_terminal_EU-GBR | D11: EU-GBR | E11: 51.70829 | F11: -5.0646298 | G11: Base | H11: =shipping_compact!$D$3 -> 938550 | I11: =shipping_compact!E$3 -> 6000 | J11: =shipping_compact!F$3 -> 30 | K11: =shipping_compact!G$3 -> 0.98 | L11: =shipping_compact!H$3 -> 0.7449745 | M11: =shipping_compact!J$3 -> 0.0325 | N11: =shipping_compact!K$3 -> 0 | O11: =shipping_compact!D$7 -> 14340589 | P11: =shipping_compact!F$7 -> 30 | Q11: =shipping_compact!G$7 -> 1 | R11: =shipping_compact!J$7 -> 0.04 | S11: =shipping_compact!L$7 -> 0 | T11: =shipping_compact!D$8 -> 144364800 | U11: =shipping_compact!E$8 -> 4380 | V11: =shipping_compact!F$8 -> 25 | W11: =shipping_compact!G$8 -> 0.987 | X11: =shipping_compact!I$8 -> 2.7777778e-06 | Y11: =shipping_compact!J$8 -> 0.04 | Z11: =shipping_compact!L$8 -> 0.00034594341 | AA11: =shipping_compact!D$9 -> 226010 | AB11: =shipping_compact!F$9 -> 30 | AC11: =shipping_compact!G$9 -> 0.98 | AD11: =shipping_compact!H$9 -> 0.98 | AE11: =shipping_compact!J$9 -> 0.03 | AF11: =shipping_compact!K$9 -> 0.0060006001
A12: terminal_AS-QAT | B12: h2liq | C12: =_xlfn.CONCAT(B12,"_",A12) -> h2liq_terminal_AS-QAT | D12: AS-QAT | E12: 25.883521 | F12: 51.480261 | G12: Base | H12: =shipping_compact!$D$3 -> 938550 | I12: =shipping_compact!E$3 -> 6000 | J12: =shipping_compact!F$3 -> 30 | K12: =shipping_compact!G$3 -> 0.98 | L12: =shipping_compact!H$3 -> 0.7449745 | M12: =shipping_compact!J$3 -> 0.0325 | N12: =shipping_compact!K$3 -> 0 | O12: =shipping_compact!D$7 -> 14340589 | P12: =shipping_compact!F$7 -> 30 | Q12: =shipping_compact!G$7 -> 1 | R12: =shipping_compact!J$7 -> 0.04 | S12: =shipping_compact!L$7 -> 0 | T12: =shipping_compact!D$8 -> 144364800 | U12: =shipping_compact!E$8 -> 4380 | V12: =shipping_compact!F$8 -> 25 | W12: =shipping_compact!G$8 -> 0.987 | X12: =shipping_compact!I$8 -> 2.7777778e-06 | Y12: =shipping_compact!J$8 -> 0.04 | Z12: =shipping_compact!L$8 -> 0.00034594341 | AA12: =shipping_compact!D$9 -> 226010 | AB12: =shipping_compact!F$9 -> 30 | AC12: =shipping_compact!G$9 -> 0.98 | AD12: =shipping_compact!H$9 -> 0.98 | AE12: =shipping_compact!J$9 -> 0.03 | AF12: =shipping_compact!K$9 -> 0.0060006001
A13: terminal_AS-IND-WE | B13: h2liq | C13: =_xlfn.CONCAT(B13,"_",A13) -> h2liq_terminal_AS-IND-WE | D13: AS-IND | E13: 18.944742 | F13: 72.950074 | G13: Base | H13: =shipping_compact!$D$3 -> 938550 | I13: =shipping_compact!E$3 -> 6000 | J13: =shipping_compact!F$3 -> 30 | K13: =shipping_compact!G$3 -> 0.98 | L13: =shipping_compact!H$3 -> 0.7449745 | M13: =shipping_compact!J$3 -> 0.0325 | N13: =shipping_compact!K$3 -> 0 | O13: =shipping_compact!D$7 -> 14340589 | P13: =shipping_compact!F$7 -> 30 | Q13: =shipping_compact!G$7 -> 1 | R13: =shipping_compact!J$7 -> 0.04 | S13: =shipping_compact!L$7 -> 0 | T13: =shipping_compact!D$8 -> 144364800 | U13: =shipping_compact!E$8 -> 4380 | V13: =shipping_compact!F$8 -> 25 | W13: =shipping_compact!G$8 -> 0.987 | X13: =shipping_compact!I$8 -> 2.7777778e-06 | Y13: =shipping_compact!J$8 -> 0.04 | Z13: =shipping_compact!L$8 -> 0.00034594341 | AA13: =shipping_compact!D$9 -> 226010 | AB13: =shipping_compact!F$9 -> 30 | AC13: =shipping_compact!G$9 -> 0.98 | AD13: =shipping_compact!H$9 -> 0.98 | AE13: =shipping_compact!J$9 -> 0.03 | AF13: =shipping_compact!K$9 -> 0.0060006001
A14: terminal_AS-IND-WE | B14: h2liq | C14: =_xlfn.CONCAT(B14,"_",A14) -> h2liq_terminal_AS-IND-WE | D14: AS-IND-WE | E14: 18.944742 | F14: 72.950074 | G14: Base | H14: =shipping_compact!$D$3 -> 938550 | I14: =shipping_compact!E$3 -> 6000 | J14: =shipping_compact!F$3 -> 30 | K14: =shipping_compact!G$3 -> 0.98 | L14: =shipping_compact!H$3 -> 0.7449745 | M14: =shipping_compact!J$3 -> 0.0325 | N14: =shipping_compact!K$3 -> 0 | O14: =shipping_compact!D$7 -> 14340589 | P14: =shipping_compact!F$7 -> 30 | Q14: =shipping_compact!G$7 -> 1 | R14: =shipping_compact!J$7 -> 0.04 | S14: =shipping_compact!L$7 -> 0 | T14: =shipping_compact!D$8 -> 144364800 | U14: =shipping_compact!E$8 -> 4380 | V14: =shipping_compact!F$8 -> 25 | W14: =shipping_compact!G$8 -> 0.987 | X14: =shipping_compact!I$8 -> 2.7777778e-06 | Y14: =shipping_compact!J$8 -> 0.04 | Z14: =shipping_compact!L$8 -> 0.00034594341 | AA14: =shipping_compact!D$9 -> 226010 | AB14: =shipping_compact!F$9 -> 30 | AC14: =shipping_compact!G$9 -> 0.98 | AD14: =shipping_compact!H$9 -> 0.98 | AE14: =shipping_compact!J$9 -> 0.03 | AF14: =shipping_compact!K$9 -> 0.0060006001
... A49: terminal_AF-EGY | B49: h2liq | C49: =_xlfn.CONCAT(B49,"_",A49) -> h2liq_terminal_AF-EGY | D49: AF-EGY | E49: 29.916289 | F49: 32.449177 | G49: Base | H49: =shipping_compact!$D$3 -> 938550 | I49: =shipping_compact!E$3 -> 6000 | J49: =shipping_compact!F$3 -> 30 | K49: =shipping_compact!G$3 -> 0.98 | L49: =shipping_compact!H$3 -> 0.7449745 | M49: =shipping_compact!J$3 -> 0.0325 | N49: =shipping_compact!K$3 -> 0 | O49: =shipping_compact!D$7 -> 14340589 | P49: =shipping_compact!F$7 -> 30 | Q49: =shipping_compact!G$7 -> 1 | R49: =shipping_compact!J$7 -> 0.04 | S49: =shipping_compact!L$7 -> 0 | T49: =shipping_compact!D$8 -> 144364800 | U49: =shipping_compact!E$8 -> 4380 | V49: =shipping_compact!F$8 -> 25 | W49: =shipping_compact!G$8 -> 0.987 | X49: =shipping_compact!I$8 -> 2.7777778e-06 | Y49: =shipping_compact!J$8 -> 0.04 | Z49: =shipping_compact!L$8 -> 0.00034594341 | AA49: =shipping_compact!D$9 -> 226010 | AB49: =shipping_compact!F$9 -> 30 | AC49: =shipping_compact!G$9 -> 0.98 | AD49: =shipping_compact!H$9 -> 0.98 | AE49: =shipping_compact!J$9 -> 0.03 | AF49: =shipping_compact!K$9 -> 0.0060006001
A50: terminal_EU-NLD | B50: nh3 | C50: =_xlfn.CONCAT(B50,"_",A50) -> nh3_terminal_EU-NLD | D50: EU-NLD | E50: 51.948455 | F50: 4.140296 | G50: Base | H50: =shipping_compact!D$12 -> 5986780 | I50: =shipping_compact!E$12 -> 6000 | J50: =shipping_compact!F$12 -> 30 | K50: =shipping_compact!G$12 -> 0.85 | L50: =shipping_compact!H$12 -> 0.992 | M50: =shipping_compact!J$12 -> 0.05 | N50: =shipping_compact!K$12 -> 0.2872 | O50: =shipping_compact!D$16 -> 293456.89 | P50: =shipping_compact!F$16 -> 30 | Q50: =shipping_compact!G$16 -> 1 | R50: =shipping_compact!J$16 -> 0.04 | S50: =shipping_compact!L$16 -> 0 | T50: =shipping_compact!D$17 -> 6181584.9 | U50: =shipping_compact!E$17 -> 4380 | V50: =shipping_compact!F$17 -> 25 | W50: =shipping_compact!G$17 -> 1 | X50: =shipping_compact!I$17 -> 0 | Y50: =shipping_compact!J$17 -> 0.04 | Z50: =shipping_compact!L$17 -> 0.0002210194 | AA50: =shipping_compact!D$18 -> 1418767 | AB50: =shipping_compact!F$18 -> 30 | AC50: =shipping_compact!G$18 -> 0.996 | AD50: =shipping_compact!H$18 -> 0.685 | AE50: =shipping_compact!J$18 -> 0.043 | AF50: =shipping_compact!K$18 -> 0
A51: terminal_EU-PRT | B51: nh3 | C51: =_xlfn.CONCAT(B51,"_",A51) -> nh3_terminal_EU-PRT | D51: EU-PRT | E51: 37.961098 | F51: -8.8786877 | G51: Base | H51: =shipping_compact!D$12 -> 5986780 | I51: =shipping_compact!E$12 -> 6000 | J51: =shipping_compact!F$12 -> 30 | K51: =shipping_compact!G$12 -> 0.85 | L51: =shipping_compact!H$12 -> 0.992 | M51: =shipping_compact!J$12 -> 0.05 | N51: =shipping_compact!K$12 -> 0.2872 | O51: =shipping_compact!D$16 -> 293456.89 | P51: =shipping_compact!F$16 -> 30 | Q51: =shipping_compact!G$16 -> 1 | R51: =shipping_compact!J$16 -> 0.04 | S51: =shipping_compact!L$16 -> 0 | T51: =shipping_compact!D$17 -> 6181584.9 | U51: =shipping_compact!E$17 -> 4380 | V51: =shipping_compact!F$17 -> 25 | W51: =shipping_compact!G$17 -> 1 | X51: =shipping_compact!I$17 -> 0 | Y51: =shipping_compact!J$17 -> 0.04 | Z51: =shipping_compact!L$17 -> 0.0002210194 | AA51: =shipping_compact!D$18 -> 1418767 | AB51: =shipping_compact!F$18 -> 30 | AC51: =shipping_compact!G$18 -> 0.996 | AD51: =shipping_compact!H$18 -> 0.685 | AE51: =shipping_compact!J$18 -> 0.043 | AF51: =shipping_compact!K$18 -> 0
A52: terminal_EU-ESP | B52: nh3 | C52: =_xlfn.CONCAT(B52,"_",A52) -> nh3_terminal_EU-ESP | D52: EU-ESP | E52: 39.463713 | F52: -0.35881979 | G52: Base | H52: =shipping_compact!D$12 -> 5986780 | I52: =shipping_compact!E$12 -> 6000 | J52: =shipping_compact!F$12 -> 30 | K52: =shipping_compact!G$12 -> 0.85 | L52: =shipping_compact!H$12 -> 0.992 | M52: =shipping_compact!J$12 -> 0.05 | N52: =shipping_compact!K$12 -> 0.2872 | O52: =shipping_compact!D$16 -> 293456.89 | P52: =shipping_compact!F$16 -> 30 | Q52: =shipping_compact!G$16 -> 1 | R52: =shipping_compact!J$16 -> 0.04 | S52: =shipping_compact!L$16 -> 0 | T52: =shipping_compact!D$17 -> 6181584.9 | U52: =shipping_compact!E$17 -> 4380 | V52: =shipping_compact!F$17 -> 25 | W52: =shipping_compact!G$17 -> 1 | X52: =shipping_compact!I$17 -> 0 | Y52: =shipping_compact!J$17 -> 0.04 | Z52: =shipping_compact!L$17 -> 0.0002210194 | AA52: =shipping_compact!D$18 -> 1418767 | AB52: =shipping_compact!F$18 -> 30 | AC52: =shipping_compact!G$18 -> 0.996 | AD52: =shipping_compact!H$18 -> 0.685 | AE52: =shipping_compact!J$18 -> 0.043 | AF52: =shipping_compact!K$18 -> 0
A53: terminal_EU-ISL | B53: nh3 | C53: =_xlfn.CONCAT(B53,"_",A53) -> nh3_terminal_EU-ISL | D53: EU-ISL | E53: 64.094858 | F53: -21.853528 | G53: Base | H53: =shipping_compact!D$12 -> 5986780 | I53: =shipping_compact!E$12 -> 6000 | J53: =shipping_compact!F$12 -> 30 | K53: =shipping_compact!G$12 -> 0.85 | L53: =shipping_compact!H$12 -> 0.992 | M53: =shipping_compact!J$12 -> 0.05 | N53: =shipping_compact!K$12 -> 0.2872 | O53: =shipping_compact!D$16 -> 293456.89 | P53: =shipping_compact!F$16 -> 30 | Q53: =shipping_compact!G$16 -> 1 | R53: =shipping_compact!J$16 -> 0.04 | S53: =shipping_compact!L$16 -> 0 | T53: =shipping_compact!D$17 -> 6181584.9 | U53: =shipping_compact!E$17 -> 4380 | V53: =shipping_compact!F$17 -> 25 | W53: =shipping_compact!G$17 -> 1 | X53: =shipping_compact!I$17 -> 0 | Y53: =shipping_compact!J$17 -> 0.04 | Z53: =shipping_compact!L$17 -> 0.0002210194 | AA53: =shipping_compact!D$18 -> 1418767 | AB53: =shipping_compact!F$18 -> 30 | AC53: =shipping_compact!G$18 -> 0.996 | AD53: =shipping_compact!H$18 -> 0.685 | AE53: =shipping_compact!J$18 -> 0.043 | AF53: =shipping_compact!K$18 -> 0
A54: terminal_EU-ITA4 | B54: nh3 | C54: =_xlfn.CONCAT(B54,"_",A54) -> nh3_terminal_EU-ITA4 | D54: EU-ITA4 | E54: 45.205817 | F54: 12.293656 | G54: Base | H54: =shipping_compact!D$12 -> 5986780 | I54: =shipping_compact!E$12 -> 6000 | J54: =shipping_compact!F$12 -> 30 | K54: =shipping_compact!G$12 -> 0.85 | L54: =shipping_compact!H$12 -> 0.992 | M54: =shipping_compact!J$12 -> 0.05 | N54: =shipping_compact!K$12 -> 0.2872 | O54: =shipping_compact!D$16 -> 293456.89 | P54: =shipping_compact!F$16 -> 30 | Q54: =shipping_compact!G$16 -> 1 | R54: =shipping_compact!J$16 -> 0.04 | S54: =shipping_compact!L$16 -> 0 | T54: =shipping_compact!D$17 -> 6181584.9 | U54: =shipping_compact!E$17 -> 4380 | V54: =shipping_compact!F$17 -> 25 | W54: =shipping_compact!G$17 -> 1 | X54: =shipping_compact!I$17 -> 0 | Y54: =shipping_compact!J$17 -> 0.04 | Z54: =shipping_compact!L$17 -> 0.0002210194 | AA54: =shipping_compact!D$18 -> 1418767 | AB54: =shipping_compact!F$18 -> 30 | AC54: =shipping_compact!G$18 -> 0.996 | AD54: =shipping_compact!H$18 -> 0.685 | AE54: =shipping_compact!J$18 -> 0.043 | AF54: =shipping_compact!K$18 -> 0
A55: terminal_EU-ITA | B55: nh3 | C55: =_xlfn.CONCAT(B55,"_",A55) -> nh3_terminal_EU-ITA | D55: EU-ITA | E55: 45.205817 | F55: 12.293656 | G55: Base | H55: =shipping_compact!D$12 -> 5986780 | I55: =shipping_compact!E$12 -> 6000 | J55: =shipping_compact!F$12 -> 30 | K55: =shipping_compact!G$12 -> 0.85 | L55: =shipping_compact!H$12 -> 0.992 | M55: =shipping_compact!J$12 -> 0.05 | N55: =shipping_compact!K$12 -> 0.2872 | O55: =shipping_compact!D$16 -> 293456.89 | P55: =shipping_compact!F$16 -> 30 | Q55: =shipping_compact!G$16 -> 1 | R55: =shipping_compact!J$16 -> 0.04 | S55: =shipping_compact!L$16 -> 0 | T55: =shipping_compact!D$17 -> 6181584.9 | U55: =shipping_compact!E$17 -> 4380 | V55: =shipping_compact!F$17 -> 25 | W55: =shipping_compact!G$17 -> 1 | X55: =shipping_compact!I$17 -> 0 | Y55: =shipping_compact!J$17 -> 0.04 | Z55: =shipping_compact!L$17 -> 0.0002210194 | AA55: =shipping_compact!D$18 -> 1418767 | AB55: =shipping_compact!F$18 -> 30 | AC55: =shipping_compact!G$18 -> 0.996 | AD55: =shipping_compact!H$18 -> 0.685 | AE55: =shipping_compact!J$18 -> 0.043 | AF55: =shipping_compact!K$18 -> 0
